<?xml version="1.0"?>
<robot name="three_wheeled_robot">

    <material name="red">
        <color rgba="1 0 0 1.0" />
    </material>

    <gazebo reference="chassis">
        <material>Gazebo/Black</material>
    </gazebo>

    <gazebo reference="laser_frame">
        <material>Gazebo/Red</material>
    </gazebo>

    <gazebo reference="front_wheel">
        <material>Gazebo/Grey</material>
    </gazebo>

    <gazebo reference="left_wheel">
        <material>Gazebo/Blue</material>
    </gazebo>


    <!-- Base Link -->
    <link name="base_link">

    </link>
    <!-- Base to chassis -->
    <joint name="Chassis_joint" type="fixed">
        <parent link="base_link" />
        <child link="chassis" />
        <origin xyz="0.25 0 0" rpy="0 0 0" />
        <axis xyz="0 1 0" />
    </joint>

    <link name="chassis">
        <visual>
            <origin rpy="0 0 0" xyz="0 0 0.075" />
            <geometry>
                <box size="0.5 0.3 0.1" />
            </geometry>
            <material name="grey">
                <color rgba="0.5 0.5 0.5 1.0" />
            </material>
        </visual>
        <collision>
            <origin rpy="0 0 0" xyz="0 0 0.075" />
            <geometry>
                <box size="0.5 0.3 0.1" />
            </geometry>
        </collision>
        <inertial>
            <mass value="5.0" />
            <inertia ixx="0.1" ixy="0.0" ixz="0.0" iyy="0.1" iyz="0.0" izz="0.1" />
        </inertial>
    </link>

    <joint name="laser_joint" type="fixed">
        <parent link="chassis" />
        <child link="laser_frame" />
        <origin xyz="0.1 0 0.175" rpy="0 0 0" />
    </joint>

    <link name="laser_frame">
        <visual>
            <geometry>
                <cylinder radius="0.05" length="0.04" />
            </geometry>
            <material name="red" />
        </visual>
        <collision>
            <geometry>
                <cylinder radius="0.05" length="0.04" />
            </geometry>
        </collision>
        <inertial>
            <mass value="0.1" />
            <inertia ixx="0.1" ixy="0.0" ixz="0.0" iyy="0.1" iyz="0.0" izz="0.1" />
        </inertial>
    </link>

    <!-- Front Wheel -->
    <link name="front_wheel">
        <visual>
            <origin xyz="0 0 0.025" rpy="1.5708 0 0" />
            <geometry>
                <sphere radius="0.05" length="0.02" />
            </geometry>
            <material name="black">
                <color rgba="0 0 0 1" />
            </material>
        </visual>
        <collision>
            <origin xyz="0 0 0.025" rpy="1.5708 0 0" />
            <geometry>
                <cylinder radius="0.05" length="0.02" />
            </geometry>
        </collision>
        <inertial>
            <mass value="0.5" />
            <inertia ixx="0.01" ixy="0.0" ixz="0.0" iyy="0.01" iyz="0.0" izz="0.01" />
        </inertial>
    </link>

    <!-- Joint: Base to Front Wheel -->
    <joint name="joint_base_to_front_wheel" type="fixed">
        <parent link="chassis" />
        <child link="front_wheel" />
        <origin xyz="0.17 0 0" rpy="0 0 0" />
        <axis xyz="0 1 0" />
    </joint>

    <!-- Left Wheel -->
    <link name="left_wheel">
        <visual>
            <origin xyz="0 0 0" rpy="1.5708 0 0" />
            <geometry>
                <cylinder radius="0.05" length="0.02" />
            </geometry>
            <material name="black">
                <color rgba="0 0 0 1" />
            </material>
        </visual>
        <collision>
            <origin xyz="0 0 0" rpy="1.5708 0 0" />
            <geometry>
                <cylinder radius="0.05" length="0.02" />
            </geometry>
        </collision>
        <inertial>
            <mass value="0.5" />
            <inertia ixx="0.01" ixy="0.0" ixz="0.0" iyy="0.01" iyz="0.0" izz="0.01" />
        </inertial>
    </link>

    <!-- Joint: Base to Left Wheel -->
    <joint name="joint_base_to_left_wheel" type="continuous">
        <parent link="chassis" />
        <child link="left_wheel" />
        <origin xyz="-0.2 0.16 0.025" rpy="0 0 0" />
        <axis xyz="0 1 0" />
    </joint>

    <!-- Right Wheel -->
    <link name="right_wheel">
        <visual>
            <origin xyz="0 0 0" rpy="1.5708 0 0" />
            <geometry>
                <cylinder radius="0.05" length="0.02" />
            </geometry>
            <material name="black">
                <color rgba="0 0 0 1" />
            </material>
        </visual>
        <collision>
            <origin xyz="0 0 0" rpy="1.5708 0 0" />
            <geometry>
                <cylinder radius="0.05" length="0.02" />
            </geometry>
        </collision>
        <inertial>
            <mass value="0.5" />
            <inertia ixx="0.01" ixy="0.0" ixz="0.0" iyy="0.01" iyz="0.0" izz="0.01" />
        </inertial>
    </link>

    <!-- Joint: Base to Right Wheel -->
    <joint name="joint_base_to_right_wheel" type="continuous">
        <parent link="chassis" />
        <child link="right_wheel" />
        <origin xyz="-0.2 -0.16 0.025" rpy="0 0 0" />
        <axis xyz="0 1 0" />
    </joint>

    <!-- Gazebo Plugin for Differential Drive -->
    <gazebo>
        <plugin name="differential_drive_controller" filename="libgazebo_ros_diff_drive.so">
            <ros>
                <namespace>/</namespace>
                <argument>odom</argument>
            </ros>
            <alwaysOn>true</alwaysOn>
            <updateRate>100</updateRate>
            <leftJoint>joint_base_to_left_wheel</leftJoint>
            <rightJoint>joint_base_to_right_wheel</rightJoint>
            <wheelSeparation>0.3</wheelSeparation>
            <wheelDiameter>0.1</wheelDiameter>
            <torque>5.0</torque>
            <commandTopic>cmd_vel</commandTopic>
            <odometryTopic>odom</odometryTopic>
            <odometryFrame>odom</odometryFrame>
            <robotBaseFrame>base_link</robotBaseFrame>
            <publishWheelTF>true</publishWheelTF>
            <publishOdomTF>true</publishOdomTF>
            <publishWheelJointState>true</publishWheelJointState>
            <wheelAcceleration>0.1</wheelAcceleration>
            <wheelTorque>10.0</wheelTorque>
            <odometrySource>0</odometrySource>
            <publishTf>true</publishTf>
        </plugin>
    </gazebo>


    <gazebo reference="laser_frame">
        <sensor type="gpu_ray" name="head_rplidar_sensor">
            <pose>0 0 0 0 0 0</pose>
            <visualize>true</visualize>
            <update_rate>10</update_rate>
            <ray>
                <scan>
                    <horizontal>
                        <samples>400</samples>
                        <resolution>1</resolution>
                        <min_angle>-3.14159</min_angle>
                        <max_angle>3.14159</max_angle>
                    </horizontal>
                </scan>
                <range>
                    <min>0.15</min>
                    <max>6.0</max>
                    <resolution>0.01</resolution>
                </range>
                <noise>
                    <type>gaussian</type>
                    <mean>0.0</mean>
                    <stddev>0.01</stddev>
                </noise>
            </ray>
            <plugin name="gazebo_ros_head_rplidar_controller" filename="libgazebo_ros_gpu_laser.so">
                <topicName>/scan</topicName>
                <frameName>laser_frame</frameName>
            </plugin>
        </sensor>
    </gazebo>


</robot>